in __main__
Exception1
2
